Workbook

Sheet 樞紐
A1: Check | B1: (多重項目)
A3: 計數 - P/N | B3: 欄標籤
A4: 列標籤 | B4: 0-30天 | C4: 31-90天 | D4: 91-180天 | E4: 365天以上 | F4: 181-365天 | G4: Closed | H4: 總計
A5: wait for return customer | B5: 6 | C5: 11 | D5: 16 | E5: 58 | F5: 95 | H5: 186
A6: on hold | B6: 31 | C6: 34 | D6: 50 | E6: 1 | F6: 7 | H6: 123
A7: VRAM is pending RTV | E7: 6 | H7: 6
A8: SBF to be notified | F8: 7 | H8: 7
A9: BU未結案 | F9: 1 | H9: 1
A10: Local Scrap | G10: 55 | H10: 55
A11: 2024Q2 | G11: 2 | H11: 2
A12: 2024Q3 | G12: 5 | H12: 5
A13: 2024Q4 | G13: 8 | H13: 8
A14: 2025Q1 | G14: 4 | H14: 4
A15: 2025Q2 | G15: 1 | H15: 1
A16: 2025Q3 | G16: 85 | H16: 85
A17: 2025Q4 | G17: 1 | H17: 1
A18: 2026Q2 | G18: 122 | H18: 122
A19: 2026Q3 | G19: 35 | H19: 35
A20: 2026Q4 | G20: 26 | H20: 26
A21: 總計 | B21: 37 | C21: 45 | D21: 66 | E21: 65 | F21: 110 | G21: 344 | H21: 667

Sheet 陣列
A1: KGB/KBB | B1: Return Customer Date | C1: Return Customer Q | D1: Sort | E1: Check
A2: {=_xlfn.LET( _xlpm.full_range, 'Search Result'!A2:V9929, _xlpm.a_col, 'Search Result'!A2:A9929, _xlpm.filtered, _xlfn._xlws.FILTER(_xlpm.full_range, _xlpm.a_col="kbb"), _xlpm.sorted, _xlfn._xlws.SORT(_xlpm.filtered, 21, -1), _xlpm.unique_data, _xlfn.UNIQUE(_xlpm.sorted, FALSE, FALSE), _xlfn.CHOOSECOLS(_xlpm.unique_data, 1, 2, 3, 4, 5) )} -> KBB | B2: 45384 | C2: 2024Q2 | D2: Closed | E2: 最新
A3: KBB | B3: Local Scrap | C3: Local Scrap | D3: Closed | E3: 最新
A4: KBB | B4: Local Scrap | C4: Local Scrap | D4: Closed | E4: 最新
A5: KBB | B5: Local Scrap | C5: Local Scrap | D5: Closed | E5: 最新
A6: KBB | B6: 45583 | C6: 2024Q4 | D6: Closed | E6: 最新
A7: KBB | B7: Local Scrap | C7: Local Scrap | D7: Closed | E7: 最新
A8: KBB | B8: Local Scrap | C8: Local Scrap | D8: Closed | E8: 最新
A9: KBB | B9: Local Scrap | C9: Local Scrap | D9: Closed | E9: 最新
A10: KBB | B10: 45852 | C10: 2025Q3 | D10: Closed | E10: 最新
A11: KBB | B11: - | C11: wait for return customer | D11: 365天以上 | E11: 最新
A12: KBB | B12: Local Scrap | C12: Local Scrap | D12: Closed | E12: 最新
A13: KBB | B13: 45659 | C13: 2025Q1 | D13: Closed | E13: 最新
A14: KBB | B14: - | C14: wait for return customer | D14: 365天以上 | E14: 最新
A15: KBB | B15: - | C15: wait for return customer | D15: 365天以上 | E15: 最新
A16: KBB | B16: - | C16: wait for return customer | D16: 365天以上 | E16: 最新
A17: KBB | B17: Local Scrap | C17: Local Scrap | D17: Closed | E17: 最新
A18: KBB | B18: Local Scrap | C18: Local Scrap | D18: Closed | E18: 最新
A19: KBB | B19: - | C19: wait for return customer | D19: 365天以上 | E19: 最新
A20: KBB | B20: - | C20: wait for return customer | D20: 365天以上 | E20: 最新
A21: KBB | B21: Local Scrap | C21: Local Scrap | D21: Closed | E21: 最新
A22: KBB | B22: Local Scrap | C22: Local Scrap | D22: Closed | E22: 最新
A23: KBB | B23: Local Scrap | C23: Local Scrap | D23: Closed | E23: 最新
A24: KBB | B24: 45762 | C24: 2025Q2 | D24: Closed | E24: 最新
A25: KBB | B25: Local Scrap | C25: Local Scrap | D25: Closed | E25: 最新
A26: KBB | B26: - | C26: wait for return customer | D26: 365天以上 | E26: 最新
A27: KBB | B27: - | C27: wait for return customer | D27: 365天以上 | E27: 最新
A28: KBB | B28: Local Scrap | C28: Local Scrap | D28: Closed | E28: 最新
A29: KBB | B29: Local Scrap | C29: Local Scrap | D29: Closed | E29: 歷史重複
A30: KBB | B30: - | C30: wait for return customer | D30: 365天以上 | E30: 最新
A31: KBB | B31: - | C31: wait for return customer | D31: 365天以上 | E31: 最新
A32: KBB | B32: 45840 | C32: 2025Q3 | D32: Closed | E32: 最新
A33: KBB | B33: - | C33: wait for return customer | D33: 365天以上 | E33: 最新
A34: KBB | B34: 45840 | C34: 2025Q3 | D34: Closed | E34: 最新
A35: KBB | B35: - | C35: wait for return customer | D35: 365天以上 | E35: 最新
A36: KBB | B36: Local Scrap | C36: Local Scrap | D36: Closed | E36: 最新
A37: KBB | B37: Local Scrap | C37: Local Scrap | D37: Closed | E37: 最新
A38: KBB | B38: Local Scrap | C38: Local Scrap | D38: Closed | E38: 最新
A39: KBB | B39: Local Scrap | C39: Local Scrap | D39: Closed | E39: 最新
A40: KBB | B40: - | C40: wait for return customer | D40: 365天以上 | E40: 最新
...

Sheet Search Result
A1: KGB/KBB | B1: Return Customer Date | C1: Return Customer Q | D1: Sort | E1: Check | F1: Order Nr | G1: Order Type | H1: Customer Type | I1: Customer Name | J1: Order Receive Date | K1: Order Apply Date | L1: Serial Nr | M1: P/N | N1: Part Desc | O1: OEM P/N | P1: Original S/N | Q1: Item Status | R1: Engineer Name | S1: Keyin Submit Date | T1: VI2 Date | U1: Ship Date | V1: Item Close Date | W1: Scrap Code | X1: Scrap Duty | Y1: Scrap Memo | Z1: Item Track Date | AA1: From Status | AB1: To Status | AC1: Last Reason Code | AD1: Model | AE1: Pack Date | AF1: BOX_ID | AG1: PACK_NO | AH1: GW | AI1: NW
A2: =IF(L2="","",IF(COUNTIF(Wip!K:K,L2)=0,IF(W2="","KGB","KBB"),IF(AND(_xlfn.IFNA(VLOOKUP(L2,Wip!K:M,3,0),"")="Y",Q2="MTCAPPLYCONF"),"On Hold",IF(W2="","KGB","KBB")))) -> KGB | B2: =IF(A2="on hold", "on hold", IF(A2="KGB", "Standard Shipment", IF(IFERROR(IFERROR(VLOOKUP(L2, List!D:J, 7, 0), VLOOKUP(L2&"", List!D:J, 7, 0)), 0)=0, IF(IFERROR(IFERROR(VLOOKUP(L2, 'CND List'!$A:$C, 3, 0), VLOOKUP(L2&"", 'CND List'!$A:$C, 3, 0)), 0)=0, IF(A2="KBB", "-", ""), IFERROR(VLOOKUP(L2, 'CND List'!$A:$C, 3, 0), VLOOKUP(L2&"", 'CND List'!$A:$C, 3, 0)) ), IFERROR(VLOOKUP(L2, List!D:J, 7, 0), VLOOKUP(L2&"", List!D:J, 7, 0)) ) ) ) -> Standard Shipment | C2: =IF(A2="on hold", "on hold", IF(B2="on hold", "wait for return customer", IF(B2="CND Sceond Pass", "Standard Shipment", IF(AND(A2="kgb", OR(B2="-", B2="", B2="#N/A")), "Standard Shipment", IF(AND(A2="kbb", OR(B2="-", B2="", B2="#N/A")), "wait for return customer", IF(OR(B2="Local Scrap", B2="SBF to be notified", B2="VRAM is pending RTV", B2="BU未結案"), B2, IF(OR(B2="scrap結案", B2="良品結案", LEFT(B2,2)="sc", LEFT(B2,2)="良品"), "CND結案", IF(ISNUMBER(B2), YEAR(B2) & "Q" & INT((MONTH(B2)+2)/3), IF(ISERROR(DATEVALUE(TEXT(B2,"yyyy/mm/dd"))), IF(ISNA(B2), "#N/A", B2), YEAR(DATEVALUE(TEXT(B2,"yyyy/mm/dd"))) & "Q" & INT((MONTH(DATEVALUE(TEXT(B2,"yyyy/mm/dd")))+2)/3)))))))))) -> Standard Shipment | D2: =IF(C2="Local Scrap","Closed",IFERROR(IF(A2="kgb","Closed",IF(MID(C2,5,1)="Q","Closed",LOOKUP(TODAY()-W2, {0,31,91,181,366}, {"0-30天","31-90天","91-180天","181-365天","365天以上"}))), LOOKUP(TODAY()-Z2, {0,31,91,181,366}, {"0-30天","31-90天","91-180天","181-365天","365天以上"}))) -> Closed | E2: {=IF(A2<>"kbb", "", IF(IFERROR(VALUE(V2), 0)=MAX(INDEX(($A$2:$A$4929="kbb")*($L$2:$L$4929=L2)*IFERROR(VALUE($V$2:$V$4929), 0), 0)), "最新", "歷史重複"))} | F2: TO241000007 | G2: R | H2: PNY | I2: PNY_Asia | J2: 2024/01/29 10:44:46 | K2: 2024/01/25 16:21:31 | L2: H723001218 | M2: 90CV07T10010 | N2: RTX4060/PG173-SKU371/GB/PNY | P2: H723001218 | Q2: CLOSED | R2: 李景福 | S2: 2024/01/29 12:23:29 | T2: 2024/02/01 17:39:15 | U2: 2024/03/15 15:07:19 | V2: 2024/03/15 15:07:19 | Z2: 2024/01/29 12:17:21 | AA2: KEYIN | AB2: KEYIN | AC2: R10 | AD2: RTX4060 | AE2: 2024/03/15 15:07:05 | AF2: 001 | AG2: 612070 | AH2: 1 | AI2: 1
A3: =IF(L3="","",IF(COUNTIF(Wip!K:K,L3)=0,IF(W3="","KGB","KBB"),IF(AND(_xlfn.IFNA(VLOOKUP(L3,Wip!K:M,3,0),"")="Y",Q3="MTCAPPLYCONF"),"On Hold",IF(W3="","KGB","KBB")))) -> KGB | B3: =IF(A3="on hold", "on hold", IF(A3="KGB", "Standard Shipment", IF(IFERROR(IFERROR(VLOOKUP(L3, List!D:J, 7, 0), VLOOKUP(L3&"", List!D:J, 7, 0)), 0)=0, IF(IFERROR(IFERROR(VLOOKUP(L3, 'CND List'!$A:$C, 3, 0), VLOOKUP(L3&"", 'CND List'!$A:$C, 3, 0)), 0)=0, IF(A3="KBB", "-", ""), IFERROR(VLOOKUP(L3, 'CND List'!$A:$C, 3, 0), VLOOKUP(L3&"", 'CND List'!$A:$C, 3, 0)) ), IFERROR(VLOOKUP(L3, List!D:J, 7, 0), VLOOKUP(L3&"", List!D:J, 7, 0)) ) ) ) -> Standard Shipment | C3: =IF(A3="on hold", "on hold", IF(B3="on hold", "wait for return customer", IF(B3="CND Sceond Pass", "Standard Shipment", IF(AND(A3="kgb", OR(B3="-", B3="", B3="#N/A")), "Standard Shipment", IF(AND(A3="kbb", OR(B3="-", B3="", B3="#N/A")), "wait for return customer", IF(OR(B3="Local Scrap", B3="SBF to be notified", B3="VRAM is pending RTV", B3="BU未結案"), B3, IF(OR(B3="scrap結案", B3="良品結案", LEFT(B3,2)="sc", LEFT(B3,2)="良品"), "CND結案", IF(ISNUMBER(B3), YEAR(B3) & "Q" & INT((MONTH(B3)+2)/3), IF(ISERROR(DATEVALUE(TEXT(B3,"yyyy/mm/dd"))), IF(ISNA(B3), "#N/A", B3), YEAR(DATEVALUE(TEXT(B3,"yyyy/mm/dd"))) & "Q" & INT((MONTH(DATEVALUE(TEXT(B3,"yyyy/mm/dd")))+2)/3)))))))))) -> Standard Shipment | D3: =IF(C3="Local Scrap","Closed",IFERROR(IF(A3="kgb","Closed",IF(MID(C3,5,1)="Q","Closed",LOOKUP(TODAY()-W3, {0,31,91,181,366}, {"0-30天","31-90天","91-180天","181-365天","365天以上"}))), LOOKUP(TODAY()-Z3, {0,31,91,181,366}, {"0-30天","31-90天","91-180天","181-365天","365天以上"}))) -> Closed | E3: {=IF(A3<>"kbb", "", IF(IFERROR(VALUE(V3), 0)=MAX(INDEX(($A$2:$A$4929="kbb")*($L$2:$L$4929=L3)*IFERROR(VALUE($V$2:$V$4929), 0), 0)), "最新", "歷史重複"))} | F3: TO241000008 | G3: R | H3: PNY | I3: PNY_Asia | J3: 2024/01/29 12:39:25 | K3: 2024/01/29 12:36:22 | L3: H723000046 | M3: 90CV07T10010 | N3: RTX4060/PG173-SKU371/GB/PNY | P3: H723000046 | Q3: CLOSED | R3: 吳崇源 | S3: 2024/01/29 13:58:28 | T3: 2024/02/01 17:40:21 | U3: 2024/03/15 15:07:20 | V3: 2024/03/15 15:07:20 | Z3: 2024/01/29 13:45:40 | AA3: KEYIN | AB3: KEYIN | AC3: R10 | AD3: RTX4060 | AE3: 2024/03/15 15:07:05 | AF3: 001 | AG3: 612070 | AH3: 1 | AI3: 1
A4: =IF(L4="","",IF(COUNTIF(Wip!K:K,L4)=0,IF(W4="","KGB","KBB"),IF(AND(_xlfn.IFNA(VLOOKUP(L4,Wip!K:M,3,0),"")="Y",Q4="MTCAPPLYCONF"),"On Hold",IF(W4="","KGB","KBB")))) -> KGB | B4: =IF(A4="on hold", "on hold", IF(A4="KGB", "Standard Shipment", IF(IFERROR(IFERROR(VLOOKUP(L4, List!D:J, 7, 0), VLOOKUP(L4&"", List!D:J, 7, 0)), 0)=0, IF(IFERROR(IFERROR(VLOOKUP(L4, 'CND List'!$A:$C, 3, 0), VLOOKUP(L4&"", 'CND List'!$A:$C, 3, 0)), 0)=0, IF(A4="KBB", "-", ""), IFERROR(VLOOKUP(L4, 'CND List'!$A:$C, 3, 0), VLOOKUP(L4&"", 'CND List'!$A:$C, 3, 0)) ), IFERROR(VLOOKUP(L4, List!D:J, 7, 0), VLOOKUP(L4&"", List!D:J, 7, 0)) ) ) ) -> Standard Shipment | C4: =IF(A4="on hold", "on hold", IF(B4="on hold", "wait for return customer", IF(B4="CND Sceond Pass", "Standard Shipment", IF(AND(A4="kgb", OR(B4="-", B4="", B4="#N/A")), "Standard Shipment", IF(AND(A4="kbb", OR(B4="-", B4="", B4="#N/A")), "wait for return customer", IF(OR(B4="Local Scrap", B4="SBF to be notified", B4="VRAM is pending RTV", B4="BU未結案"), B4, IF(OR(B4="scrap結案", B4="良品結案", LEFT(B4,2)="sc", LEFT(B4,2)="良品"), "CND結案", IF(ISNUMBER(B4), YEAR(B4) & "Q" & INT((MONTH(B4)+2)/3), IF(ISERROR(DATEVALUE(TEXT(B4,"yyyy/mm/dd"))), IF(ISNA(B4), "#N/A", B4), YEAR(DATEVALUE(TEXT(B4,"yyyy/mm/dd"))) & "Q" & INT((MONTH(DATEVALUE(TEXT(B4,"yyyy/mm/dd")))+2)/3)))))))))) -> Standard Shipment | D4: =IF(C4="Local Scrap","Closed",IFERROR(IF(A4="kgb","Closed",IF(MID(C4,5,1)="Q","Closed",LOOKUP(TODAY()-W4, {0,31,91,181,366}, {"0-30天","31-90天","91-180天","181-365天","365天以上"}))), LOOKUP(TODAY()-Z4, {0,31,91,181,366}, {"0-30天","31-90天","91-180天","181-365天","365天以上"}))) -> Closed | E4: {=IF(A4<>"kbb", "", IF(IFERROR(VALUE(V4), 0)=MAX(INDEX(($A$2:$A$4929="kbb")*($L$2:$L$4929=L4)*IFERROR(VALUE($V$2:$V$4929), 0), 0)), "最新", "歷史重複"))} | F4: TO241000008 | G4: R | H4: PNY | I4: PNY_Asia | J4: 2024/01/29 12:39:25 | K4: 2024/01/29 12:36:22 | L4: H723001022 | M4: 90CV07T10010 | N4: RTX4060/PG173-SKU371/GB/PNY | P4: H723001022 | Q4: CLOSED | R4: 吳崇源 | S4: 2024/01/29 13:58:28 | T4: 2024/04/25 12:35:15 | U4: 2024/04/30 16:55:57 | V4: 2024/04/30 16:55:58 | Z4: 2024/01/29 13:40:53 | AA4: KEYIN | AB4: KEYIN | AC4: R10 | AD4: RTX4060 | AE4: 2024/04/30 16:55:37 | AF4: 001 | AG4: 613632 | AH4: 1 | AI4: 1
A5: =IF(L5="","",IF(COUNTIF(Wip!K:K,L5)=0,IF(W5="","KGB","KBB"),IF(AND(_xlfn.IFNA(VLOOKUP(L5,Wip!K:M,3,0),"")="Y",Q5="MTCAPPLYCONF"),"On Hold",IF(W5="","KGB","KBB")))) -> KGB | B5: =IF(A5="on hold", "on hold", IF(A5="KGB", "Standard Shipment", IF(IFERROR(IFERROR(VLOOKUP(L5, List!D:J, 7, 0), VLOOKUP(L5&"", List!D:J, 7, 0)), 0)=0, IF(IFERROR(IFERROR(VLOOKUP(L5, 'CND List'!$A:$C, 3, 0), VLOOKUP(L5&"", 'CND List'!$A:$C, 3, 0)), 0)=0, IF(A5="KBB", "-", ""), IFERROR(VLOOKUP(L5, 'CND List'!$A:$C, 3, 0), VLOOKUP(L5&"", 'CND List'!$A:$C, 3, 0)) ), IFERROR(VLOOKUP(L5, List!D:J, 7, 0), VLOOKUP(L5&"", List!D:J, 7, 0)) ) ) ) -> Standard Shipment | C5: =IF(A5="on hold", "on hold", IF(B5="on hold", "wait for return customer", IF(B5="CND Sceond Pass", "Standard Shipment", IF(AND(A5="kgb", OR(B5="-", B5="", B5="#N/A")), "Standard Shipment", IF(AND(A5="kbb", OR(B5="-", B5="", B5="#N/A")), "wait for return customer", IF(OR(B5="Local Scrap", B5="SBF to be notified", B5="VRAM is pending RTV", B5="BU未結案"), B5, IF(OR(B5="scrap結案", B5="良品結案", LEFT(B5,2)="sc", LEFT(B5,2)="良品"), "CND結案", IF(ISNUMBER(B5), YEAR(B5) & "Q" & INT((MONTH(B5)+2)/3), IF(ISERROR(DATEVALUE(TEXT(B5,"yyyy/mm/dd"))), IF(ISNA(B5), "#N/A", B5), YEAR(DATEVALUE(TEXT(B5,"yyyy/mm/dd"))) & "Q" & INT((MONTH(DATEVALUE(TEXT(B5,"yyyy/mm/dd")))+2)/3)))))))))) -> Standard Shipment | D5: =IF(C5="Local Scrap","Closed",IFERROR(IF(A5="kgb","Closed",IF(MID(C5,5,1)="Q","Closed",LOOKUP(TODAY()-W5, {0,31,91,181,366}, {"0-30天","31-90天","91-180天","181-365天","365天以上"}))), LOOKUP(TODAY()-Z5, {0,31,91,181,366}, {"0-30天","31-90天","91-180天","181-365天","365天以上"}))) -> Closed | E5: {=IF(A5<>"kbb", "", IF(IFERROR(VALUE(V5), 0)=MAX(INDEX(($A$2:$A$4929="kbb")*($L$2:$L$4929=L5)*IFERROR(VALUE($V$2:$V$4929), 0), 0)), "最新", "歷史重複"))} | F5: TO241000008 | G5: R | H5: PNY | I5: PNY_Asia | J5: 2024/01/29 12:39:25 | K5: 2024/01/29 12:36:22 | L5: H723001037 | M5: 90CV07T10010 | N5: RTX4060/PG173-SKU371/GB/PNY | P5: H723001037 | Q5: CLOSED | R5: 吳崇源 | S5: 2024/01/29 13:58:28 | T5: 2024/02/01 17:39:54 | U5: 2024/03/15 15:07:20 | V5: 2024/03/15 15:07:20 | Z5: 2024/01/29 13:42:07 | AA5: KEYIN | AB5: KEYIN | AC5: R10 | AD5: RTX4060 | AE5: 2024/03/15 15:07:05 | AF5: 001 | AG5: 612070 | AH5: 1 | AI5: 1
A6: =IF(L6="","",IF(COUNTIF(Wip!K:K,L6)=0,IF(W6="","KGB","KBB"),IF(AND(_xlfn.IFNA(VLOOKUP(L6,Wip!K:M,3,0),"")="Y",Q6="MTCAPPLYCONF"),"On Hold",IF(W6="","KGB","KBB")))) -> KGB | B6: =IF(A6="on hold", "on hold", IF(A6="KGB", "Standard Shipment", IF(IFERROR(IFERROR(VLOOKUP(L6, List!D:J, 7, 0), VLOOKUP(L6&"", List!D:J, 7, 0)), 0)=0, IF(IFERROR(IFERROR(VLOOKUP(L6, 'CND List'!$A:$C, 3, 0), VLOOKUP(L6&"", 'CND List'!$A:$C, 3, 0)), 0)=0, IF(A6="KBB", "-", ""), IFERROR(VLOOKUP(L6, 'CND List'!$A:$C, 3, 0), VLOOKUP(L6&"", 'CND List'!$A:$C, 3, 0)) ), IFERROR(VLOOKUP(L6, List!D:J, 7, 0), VLOOKUP(L6&"", List!D:J, 7, 0)) ) ) ) -> Standard Shipment | C6: =IF(A6="on hold", "on hold", IF(B6="on hold", "wait for return customer", IF(B6="CND Sceond Pass", "Standard Shipment", IF(AND(A6="kgb", OR(B6="-", B6="", B6="#N/A")), "Standard Shipment", IF(AND(A6="kbb", OR(B6="-", B6="", B6="#N/A")), "wait for return customer", IF(OR(B6="Local Scrap", B6="SBF to be notified", B6="VRAM is pending RTV", B6="BU未結案"), B6, IF(OR(B6="scrap結案", B6="良品結案", LEFT(B6,2)="sc", LEFT(B6,2)="良品"), "CND結案", IF(ISNUMBER(B6), YEAR(B6) & "Q" & INT((MONTH(B6)+2)/3), IF(ISERROR(DATEVALUE(TEXT(B6,"yyyy/mm/dd"))), IF(ISNA(B6), "#N/A", B6), YEAR(DATEVALUE(TEXT(B6,"yyyy/mm/dd"))) & "Q" & INT((MONTH(DATEVALUE(TEXT(B6,"yyyy/mm/dd")))+2)/3)))))))))) -> Standard Shipment | D6: =IF(C6="Local Scrap","Closed",IFERROR(IF(A6="kgb","Closed",IF(MID(C6,5,1)="Q","Closed",LOOKUP(TODAY()-W6, {0,31,91,181,366}, {"0-30天","31-90天","91-180天","181-365天","365天以上"}))), LOOKUP(TODAY()-Z6, {0,31,91,181,366}, {"0-30天","31-90天","91-180天","181-365天","365天以上"}))) -> Closed | E6: {=IF(A6<>"kbb", "", IF(IFERROR(VALUE(V6), 0)=MAX(INDEX(($A$2:$A$4929="kbb")*($L$2:$L$4929=L6)*IFERROR(VALUE($V$2:$V$4929), 0), 0)), "最新", "歷史重複"))} | F6: TO241000008 | G6: R | H6: PNY | I6: PNY_Asia | J6: 2024/01/29 12:39:25 | K6: 2024/01/29 12:36:22 | L6: H723004437 | M6: 90CV07T10090 | N6: RTX4060/PG173-SKU371/GB/PNY | P6: H723004437 | Q6: CLOSED | R6: 吳崇源 | S6: 2024/01/29 13:58:28 | T6: 2024/02/01 17:40:37 | U6: 2024/03/15 15:07:20 | V6: 2024/03/15 15:07:20 | Z6: 2024/01/29 13:43:16 | AA6: KEYIN | AB6: KEYIN | AC6: R10 | AD6: RTX4060 | AE6: 2024/03/15 15:07:05 | AF6: 001 | AG6: 612070 | AH6: 1 | AI6: 1
A7: =IF(L7="","",IF(COUNTIF(Wip!K:K,L7)=0,IF(W7="","KGB","KBB"),IF(AND(_xlfn.IFNA(VLOOKUP(L7,Wip!K:M,3,0),"")="Y",Q7="MTCAPPLYCONF"),"On Hold",IF(W7="","KGB","KBB")))) -> KGB | B7: =IF(A7="on hold", "on hold", IF(A7="KGB", "Standard Shipment", IF(IFERROR(IFERROR(VLOOKUP(L7, List!D:J, 7, 0), VLOOKUP(L7&"", List!D:J, 7, 0)), 0)=0, IF(IFERROR(IFERROR(VLOOKUP(L7, 'CND List'!$A:$C, 3, 0), VLOOKUP(L7&"", 'CND List'!$A:$C, 3, 0)), 0)=0, IF(A7="KBB", "-", ""), IFERROR(VLOOKUP(L7, 'CND List'!$A:$C, 3, 0), VLOOKUP(L7&"", 'CND List'!$A:$C, 3, 0)) ), IFERROR(VLOOKUP(L7, List!D:J, 7, 0), VLOOKUP(L7&"", List!D:J, 7, 0)) ) ) ) -> Standard Shipment | C7: =IF(A7="on hold", "on hold", IF(B7="on hold", "wait for return customer", IF(B7="CND Sceond Pass", "Standard Shipment", IF(AND(A7="kgb", OR(B7="-", B7="", B7="#N/A")), "Standard Shipment", IF(AND(A7="kbb", OR(B7="-", B7="", B7="#N/A")), "wait for return customer", IF(OR(B7="Local Scrap", B7="SBF to be notified", B7="VRAM is pending RTV", B7="BU未結案"), B7, IF(OR(B7="scrap結案", B7="良品結案", LEFT(B7,2)="sc", LEFT(B7,2)="良品"), "CND結案", IF(ISNUMBER(B7), YEAR(B7) & "Q" & INT((MONTH(B7)+2)/3), IF(ISERROR(DATEVALUE(TEXT(B7,"yyyy/mm/dd"))), IF(ISNA(B7), "#N/A", B7), YEAR(DATEVALUE(TEXT(B7,"yyyy/mm/dd"))) & "Q" & INT((MONTH(DATEVALUE(TEXT(B7,"yyyy/mm/dd")))+2)/3)))))))))) -> Standard Shipment | D7: =IF(C7="Local Scrap","Closed",IFERROR(IF(A7="kgb","Closed",IF(MID(C7,5,1)="Q","Closed",LOOKUP(TODAY()-W7, {0,31,91,181,366}, {"0-30天","31-90天","91-180天","181-365天","365天以上"}))), LOOKUP(TODAY()-Z7, {0,31,91,181,366}, {"0-30天","31-90天","91-180天","181-365天","365天以上"}))) -> Closed | E7: {=IF(A7<>"kbb", "", IF(IFERROR(VALUE(V7), 0)=MAX(INDEX(($A$2:$A$4929="kbb")*($L$2:$L$4929=L7)*IFERROR(VALUE($V$2:$V$4929), 0), 0)), "最新", "歷史重複"))} | F7: TO241000008 | G7: R | H7: PNY | I7: PNY_Asia | J7: 2024/01/29 12:39:25 | K7: 2024/01/29 12:36:22 | L7: H723000600 | M7: 90CV07T10010 | N7: RTX4060/PG173-SKU371/GB/PNY | P7: H723000600 | Q7: CLOSED | R7: 李景福 | S7: 2024/01/29 13:58:28 | T7: 2024/02/01 17:39:32 | U7: 2024/03/15 15:07:20 | V7: 2024/03/15 15:07:20 | Z7: 2024/01/29 13:47:31 | AA7: KEYIN | AB7: KEYIN | AC7: R10 | AD7: RTX4060 | AE7: 2024/03/15 15:07:05 | AF7: 001 | AG7: 612070 | AH7: 1 | AI7: 1
A8: =IF(L8="","",IF(COUNTIF(Wip!K:K,L8)=0,IF(W8="","KGB","KBB"),IF(AND(_xlfn.IFNA(VLOOKUP(L8,Wip!K:M,3,0),"")="Y",Q8="MTCAPPLYCONF"),"On Hold",IF(W8="","KGB","KBB")))) -> KGB | B8: =IF(A8="on hold", "on hold", IF(A8="KGB", "Standard Shipment", IF(IFERROR(IFERROR(VLOOKUP(L8, List!D:J, 7, 0), VLOOKUP(L8&"", List!D:J, 7, 0)), 0)=0, IF(IFERROR(IFERROR(VLOOKUP(L8, 'CND List'!$A:$C, 3, 0), VLOOKUP(L8&"", 'CND List'!$A:$C, 3, 0)), 0)=0, IF(A8="KBB", "-", ""), IFERROR(VLOOKUP(L8, 'CND List'!$A:$C, 3, 0), VLOOKUP(L8&"", 'CND List'!$A:$C, 3, 0)) ), IFERROR(VLOOKUP(L8, List!D:J, 7, 0), VLOOKUP(L8&"", List!D:J, 7, 0)) ) ) ) -> Standard Shipment | C8: =IF(A8="on hold", "on hold", IF(B8="on hold", "wait for return customer", IF(B8="CND Sceond Pass", "Standard Shipment", IF(AND(A8="kgb", OR(B8="-", B8="", B8="#N/A")), "Standard Shipment", IF(AND(A8="kbb", OR(B8="-", B8="", B8="#N/A")), "wait for return customer", IF(OR(B8="Local Scrap", B8="SBF to be notified", B8="VRAM is pending RTV", B8="BU未結案"), B8, IF(OR(B8="scrap結案", B8="良品結案", LEFT(B8,2)="sc", LEFT(B8,2)="良品"), "CND結案", IF(ISNUMBER(B8), YEAR(B8) & "Q" & INT((MONTH(B8)+2)/3), IF(ISERROR(DATEVALUE(TEXT(B8,"yyyy/mm/dd"))), IF(ISNA(B8), "#N/A", B8), YEAR(DATEVALUE(TEXT(B8,"yyyy/mm/dd"))) & "Q" & INT((MONTH(DATEVALUE(TEXT(B8,"yyyy/mm/dd")))+2)/3)))))))))) -> Standard Shipment | D8: =IF(C8="Local Scrap","Closed",IFERROR(IF(A8="kgb","Closed",IF(MID(C8,5,1)="Q","Closed",LOOKUP(TODAY()-W8, {0,31,91,181,366}, {"0-30天","31-90天","91-180天","181-365天","365天以上"}))), LOOKUP(TODAY()-Z8, {0,31,91,181,366}, {"0-30天","31-90天","91-180天","181-365天","365天以上"}))) -> Closed | E8: {=IF(A8<>"kbb", "", IF(IFERROR(VALUE(V8), 0)=MAX(INDEX(($A$2:$A$4929="kbb")*($L$2:$L$4929=L8)*IFERROR(VALUE($V$2:$V$4929), 0), 0)), "最新", "歷史重複"))} | F8: TO241000008 | G8: R | H8: PNY | I8: PNY_Asia | J8: 2024/01/29 12:39:25 | K8: 2024/01/29 12:36:22 | L8: H723001224 | M8: 90CV07T10010 | N8: RTX4060/PG173-SKU371/GB/PNY | P8: H723001224 | Q8: CLOSED | R8: 吳崇源 | S8: 2024/01/29 13:58:28 | T8: 2024/04/25 12:35:26 | U8: 2024/04/30 16:55:57 | V8: 2024/04/30 16:55:58 | Z8: 2024/01/29 13:37:01 | AA8: KEYIN | AB8: KEYIN | AC8: R10 | AD8: RTX4060 | AE8: 2024/04/30 16:55:37 | AF8: 001 | AG8: 613632 | AH8: 1 | AI8: 1
A9: =IF(L9="","",IF(COUNTIF(Wip!K:K,L9)=0,IF(W9="","KGB","KBB"),IF(AND(_xlfn.IFNA(VLOOKUP(L9,Wip!K:M,3,0),"")="Y",Q9="MTCAPPLYCONF"),"On Hold",IF(W9="","KGB","KBB")))) -> KGB | B9: =IF(A9="on hold", "on hold", IF(A9="KGB", "Standard Shipment", IF(IFERROR(IFERROR(VLOOKUP(L9, List!D:J, 7, 0), VLOOKUP(L9&"", List!D:J, 7, 0)), 0)=0, IF(IFERROR(IFERROR(VLOOKUP(L9, 'CND List'!$A:$C, 3, 0), VLOOKUP(L9&"", 'CND List'!$A:$C, 3, 0)), 0)=0, IF(A9="KBB", "-", ""), IFERROR(VLOOKUP(L9, 'CND List'!$A:$C, 3, 0), VLOOKUP(L9&"", 'CND List'!$A:$C, 3, 0)) ), IFERROR(VLOOKUP(L9, List!D:J, 7, 0), VLOOKUP(L9&"", List!D:J, 7, 0)) ) ) ) -> Standard Shipment | C9: =IF(A9="on hold", "on hold", IF(B9="on hold", "wait for return customer", IF(B9="CND Sceond Pass", "Standard Shipment", IF(AND(A9="kgb", OR(B9="-", B9="", B9="#N/A")), "Standard Shipment", IF(AND(A9="kbb", OR(B9="-", B9="", B9="#N/A")), "wait for return customer", IF(OR(B9="Local Scrap", B9="SBF to be notified", B9="VRAM is pending RTV", B9="BU未結案"), B9, IF(OR(B9="scrap結案", B9="良品結案", LEFT(B9,2)="sc", LEFT(B9,2)="良品"), "CND結案", IF(ISNUMBER(B9), YEAR(B9) & "Q" & INT((MONTH(B9)+2)/3), IF(ISERROR(DATEVALUE(TEXT(B9,"yyyy/mm/dd"))), IF(ISNA(B9), "#N/A", B9), YEAR(DATEVALUE(TEXT(B9,"yyyy/mm/dd"))) & "Q" & INT((MONTH(DATEVALUE(TEXT(B9,"yyyy/mm/dd")))+2)/3)))))))))) -> Standard Shipment | D9: =IF(C9="Local Scrap","Closed",IFERROR(IF(A9="kgb","Closed",IF(MID(C9,5,1)="Q","Closed",LOOKUP(TODAY()-W9, {0,31,91,181,366}, {"0-30天","31-90天","91-180天","181-365天","365天以上"}))), LOOKUP(TODAY()-Z9, {0,31,91,181,366}, {"0-30天","31-90天","91-180天","181-365天","365天以上"}))) -> Closed | E9: {=IF(A9<>"kbb", "", IF(IFERROR(VALUE(V9), 0)=MAX(INDEX(($A$2:$A$4929="kbb")*($L$2:$L$4929=L9)*IFERROR(VALUE($V$2:$V$4929), 0), 0)), "最新", "歷史重複"))} | F9: TO243000002 | G9: R | H9: PNY | I9: PNY_Asia | J9: 2024/03/05 16:35:59 | K9: 2024/03/04 11:16:54 | L9: HO23004543 | M9: 90CV07U100A0 | N9: RTX4060TI/PG190SKU361/GB/PNY | P9: HO23004543 | Q9: CLOSED | R9: 李景福 | S9: 2024/03/08 10:44:06 | T9: 2024/04/02 10:52:33 | U9: 2024/04/02 12:27:02 | V9: 2024/04/02 12:27:02 | Z9: 2024/03/08 10:37:50 | AA9: KEYIN | AB9: KEYIN | AC9: R10 | AD9: RTX4060TI | AE9: 2024/04/02 12:22:23 | AF9: 001 | AG9: 612776 | AH9: 1 | AI9: 1
A10: =IF(L10="","",IF(COUNTIF(Wip!K:K,L10)=0,IF(W10="","KGB","KBB"),IF(AND(_xlfn.IFNA(VLOOKUP(L10,Wip!K:M,3,0),"")="Y",Q10="MTCAPPLYCONF"),"On Hold",IF(W10="","KGB","KBB")))) -> KGB | B10: =IF(A10="on hold", "on hold", IF(A10="KGB", "Standard Shipment", IF(IFERROR(IFERROR(VLOOKUP(L10, List!D:J, 7, 0), VLOOKUP(L10&"", List!D:J, 7, 0)), 0)=0, IF(IFERROR(IFERROR(VLOOKUP(L10, 'CND List'!$A:$C, 3, 0), VLOOKUP(L10&"", 'CND List'!$A:$C, 3, 0)), 0)=0, IF(A10="KBB", "-", ""), IFERROR(VLOOKUP(L10, 'CND List'!$A:$C, 3, 0), VLOOKUP(L10&"", 'CND List'!$A:$C, 3, 0)) ), IFERROR(VLOOKUP(L10, List!D:J, 7, 0), VLOOKUP(L10&"", List!D:J, 7, 0)) ) ) ) -> Standard Shipment | C10: =IF(A10="on hold", "on hold", IF(B10="on hold", "wait for return customer", IF(B10="CND Sceond Pass", "Standard Shipment", IF(AND(A10="kgb", OR(B10="-", B10="", B10="#N/A")), "Standard Shipment", IF(AND(A10="kbb", OR(B10="-", B10="", B10="#N/A")), "wait for return customer", IF(OR(B10="Local Scrap", B10="SBF to be notified", B10="VRAM is pending RTV", B10="BU未結案"), B10, IF(OR(B10="scrap結案", B10="良品結案", LEFT(B10,2)="sc", LEFT(B10,2)="良品"), "CND結案", IF(ISNUMBER(B10), YEAR(B10) & "Q" & INT((MONTH(B10)+2)/3), IF(ISERROR(DATEVALUE(TEXT(B10,"yyyy/mm/dd"))), IF(ISNA(B10), "#N/A", B10), YEAR(DATEVALUE(TEXT(B10,"yyyy/mm/dd"))) & "Q" & INT((MONTH(DATEVALUE(TEXT(B10,"yyyy/mm/dd")))+2)/3)))))))))) -> Standard Shipment | D10: =IF(C10="Local Scrap","Closed",IFERROR(IF(A10="kgb","Closed",IF(MID(C10,5,1)="Q","Closed",LOOKUP(TODAY()-W10, {0,31,91,181,366}, {"0-30天","31-90天","91-180天","181-365天","365天以上"}))), LOOKUP(TODAY()-Z10, {0,31,91,181,366}, {"0-30天","31-90天","91-180天","181-365天","365天以上"}))) -> Closed | E10: {=IF(A10<>"kbb", "", IF(IFERROR(VALUE(V10), 0)=MAX(INDEX(($A$2:$A$4929="kbb")*($L$2:$L$4929=L10)*IFERROR(VALUE($V$2:$V$4929), 0), 0)), "最新", "歷史重複"))} | F10: TO243000002 | G10: R | H10: PNY | I10: PNY_Asia | J10: 2024/03/05 16:35:59 | K10: 2024/03/04 11:16:54 | L10: HN23008369 | M10: 90CV07T10050 | N10: RTX4060/PG173-SKU371/GB/PNY | P10: HN23008369 | Q10: CLOSED | R10: 李景福 | S10: 2024/03/08 10:44:06 | T10: 2024/04/25 12:34:05 | U10: 2024/04/30 16:55:57 | V10: 2024/04/30 16:55:58 | Z10: 2024/03/08 10:33:31 | AA10: KEYIN | AB10: KEYIN | AC10: R10 | AD10: RTX4060 | AE10: 2024/04/30 16:55:37 | AF10: 001 | AG10: 613632 | AH10: 1 | AI10: 1
A11: =IF(L11="","",IF(COUNTIF(Wip!K:K,L11)=0,IF(W11="","KGB","KBB"),IF(AND(_xlfn.IFNA(VLOOKUP(L11,Wip!K:M,3,0),"")="Y",Q11="MTCAPPLYCONF"),"On Hold",IF(W11="","KGB","KBB")))) -> KGB | B11: =IF(A11="on hold", "on hold", IF(A11="KGB", "Standard Shipment", IF(IFERROR(IFERROR(VLOOKUP(L11, List!D:J, 7, 0), VLOOKUP(L11&"", List!D:J, 7, 0)), 0)=0, IF(IFERROR(IFERROR(VLOOKUP(L11, 'CND List'!$A:$C, 3, 0), VLOOKUP(L11&"", 'CND List'!$A:$C, 3, 0)), 0)=0, IF(A11="KBB", "-", ""), IFERROR(VLOOKUP(L11, 'CND List'!$A:$C, 3, 0), VLOOKUP(L11&"", 'CND List'!$A:$C, 3, 0)) ), IFERROR(VLOOKUP(L11, List!D:J, 7, 0), VLOOKUP(L11&"", List!D:J, 7, 0)) ) ) ) -> Standard Shipment | C11: =IF(A11="on hold", "on hold", IF(B11="on hold", "wait for return customer", IF(B11="CND Sceond Pass", "Standard Shipment", IF(AND(A11="kgb", OR(B11="-", B11="", B11="#N/A")), "Standard Shipment", IF(AND(A11="kbb", OR(B11="-", B11="", B11="#N/A")), "wait for return customer", IF(OR(B11="Local Scrap", B11="SBF to be notified", B11="VRAM is pending RTV", B11="BU未結案"), B11, IF(OR(B11="scrap結案", B11="良品結案", LEFT(B11,2)="sc", LEFT(B11,2)="良品"), "CND結案", IF(ISNUMBER(B11), YEAR(B11) & "Q" & INT((MONTH(B11)+2)/3), IF(ISERROR(DATEVALUE(TEXT(B11,"yyyy/mm/dd"))), IF(ISNA(B11), "#N/A", B11), YEAR(DATEVALUE(TEXT(B11,"yyyy/mm/dd"))) & "Q" & INT((MONTH(DATEVALUE(TEXT(B11,"yyyy/mm/dd")))+2)/3)))))))))) -> Standard Shipment | D11: =IF(C11="Local Scrap","Closed",IFERROR(IF(A11="kgb","Closed",IF(MID(C11,5,1)="Q","Closed",LOOKUP(TODAY()-W11, {0,31,91,181,366}, {"0-30天","31-90天","91-180天","181-365天","365天以上"}))), LOOKUP(TODAY()-Z11, {0,31,91,181,366}, {"0-30天","31-90天","91-180天","181-365天","365天以上"}))) -> Closed | E11: {=IF(A11<>"kbb", "", IF(IFERROR(VALUE(V11), 0)=MAX(INDEX(($A$2:$A$4929="kbb")*($L$2:$L$4929=L11)*IFERROR(VALUE($V$2:$V$4929), 0), 0)), "最新", "歷史重複"))} | F11: TO243000002 | G11: R | H11: PNY | I11: PNY_Asia | J11: 2024/03/05 16:35:59 | K11: 2024/03/04 11:16:54 | L11: HN23008489 | M11: 90CV07T10050 | N11: RTX4060/PG173-SKU371/GB/PNY | P11: HN23008489 | Q11: CLOSED | R11: 李景福 | S11: 2024/03/08 10:44:06 | T11: 2024/04/25 12:34:16 | U11: 2024/04/30 16:55:57 | V11: 2024/04/30 16:55:58 | Z11: 2024/03/08 10:29:21 | AA11: KEYIN | AB11: KEYIN | AC11: R10 | AD11: RTX4060 | AE11: 2024/04/30 16:55:37 | AF11: 001 | AG11: 613632 | AH11: 1 | AI11: 1
A12: =IF(L12="","",IF(COUNTIF(Wip!K:K,L12)=0,IF(W12="","KGB","KBB"),IF(AND(_xlfn.IFNA(VLOOKUP(L12,Wip!K:M,3,0),"")="Y",Q12="MTCAPPLYCONF"),"On Hold",IF(W12="","KGB","KBB")))) -> KGB | B12: =IF(A12="on hold", "on hold", IF(A12="KGB", "Standard Shipment", IF(IFERROR(IFERROR(VLOOKUP(L12, List!D:J, 7, 0), VLOOKUP(L12&"", List!D:J, 7, 0)), 0)=0, IF(IFERROR(IFERROR(VLOOKUP(L12, 'CND List'!$A:$C, 3, 0), VLOOKUP(L12&"", 'CND List'!$A:$C, 3, 0)), 0)=0, IF(A12="KBB", "-", ""), IFERROR(VLOOKUP(L12, 'CND List'!$A:$C, 3, 0), VLOOKUP(L12&"", 'CND List'!$A:$C, 3, 0)) ), IFERROR(VLOOKUP(L12, List!D:J, 7, 0), VLOOKUP(L12&"", List!D:J, 7, 0)) ) ) ) -> Standard Shipment | C12: =IF(A12="on hold", "on hold", IF(B12="on hold", "wait for return customer", IF(B12="CND Sceond Pass", "Standard Shipment", IF(AND(A12="kgb", OR(B12="-", B12="", B12="#N/A")), "Standard Shipment", IF(AND(A12="kbb", OR(B12="-", B12="", B12="#N/A")), "wait for return customer", IF(OR(B12="Local Scrap", B12="SBF to be notified", B12="VRAM is pending RTV", B12="BU未結案"), B12, IF(OR(B12="scrap結案", B12="良品結案", LEFT(B12,2)="sc", LEFT(B12,2)="良品"), "CND結案", IF(ISNUMBER(B12), YEAR(B12) & "Q" & INT((MONTH(B12)+2)/3), IF(ISERROR(DATEVALUE(TEXT(B12,"yyyy/mm/dd"))), IF(ISNA(B12), "#N/A", B12), YEAR(DATEVALUE(TEXT(B12,"yyyy/mm/dd"))) & "Q" & INT((MONTH(DATEVALUE(TEXT(B12,"yyyy/mm/dd")))+2)/3)))))))))) -> Standard Shipment | D12: =IF(C12="Local Scrap","Closed",IFERROR(IF(A12="kgb","Closed",IF(MID(C12,5,1)="Q","Closed",LOOKUP(TODAY()-W12, {0,31,91,181,366}, {"0-30天","31-90天","91-180天","181-365天","365天以上"}))), LOOKUP(TODAY()-Z12, {0,31,91,181,366}, {"0-30天","31-90天","91-180天","181-365天","365天以上"}))) -> Closed | E12: {=IF(A12<>"kbb", "", IF(IFERROR(VALUE(V12), 0)=MAX(INDEX(($A$2:$A$4929="kbb")*($L$2:$L$4929=L12)*IFERROR(VALUE($V$2:$V$4929), 0), 0)), "最新", "歷史重複"))} | F12: TO243000002 | G12: R | H12: PNY | I12: PNY_Asia | J12: 2024/03/05 16:35:59 | K12: 2024/03/04 11:16:54 | L12: HO23003390 | M12: 90CV07U100A0 | N12: RTX4060TI/PG190SKU361/GB/PNY | P12: HO23003390 | Q12: CLOSED | R12: 李景福 | S12: 2024/03/08 10:44:06 | T12: 2024/04/02 10:52:40 | U12: 2024/04/02 12:27:02 | V12: 2024/04/02 12:27:02 | Z12: 2024/03/08 10:28:09 | AA12: KEYIN | AB12: KEYIN | AC12: R10 | AD12: RTX4060TI | AE12: 2024/04/02 12:22:23 | AF12: 001 | AG12: 612776 | AH12: 1 | AI12: 1
A13: =IF(L13="","",IF(COUNTIF(Wip!K:K,L13)=0,IF(W13="","KGB","KBB"),IF(AND(_xlfn.IFNA(VLOOKUP(L13,Wip!K:M,3,0),"")="Y",Q13="MTCAPPLYCONF"),"On Hold",IF(W13="","KGB","KBB")))) -> KGB | B13: =IF(A13="on hold", "on hold", IF(A13="KGB", "Standard Shipment", IF(IFERROR(IFERROR(VLOOKUP(L13, List!D:J, 7, 0), VLOOKUP(L13&"", List!D:J, 7, 0)), 0)=0, IF(IFERROR(IFERROR(VLOOKUP(L13, 'CND List'!$A:$C, 3, 0), VLOOKUP(L13&"", 'CND List'!$A:$C, 3, 0)), 0)=0, IF(A13="KBB", "-", ""), IFERROR(VLOOKUP(L13, 'CND List'!$A:$C, 3, 0), VLOOKUP(L13&"", 'CND List'!$A:$C, 3, 0)) ), IFERROR(VLOOKUP(L13, List!D:J, 7, 0), VLOOKUP(L13&"", List!D:J, 7, 0)) ) ) ) -> Standard Shipment | C13: =IF(A13="on hold", "on hold", IF(B13="on hold", "wait for return customer", IF(B13="CND Sceond Pass", "Standard Shipment", IF(AND(A13="kgb", OR(B13="-", B13="", B13="#N/A")), "Standard Shipment", IF(AND(A13="kbb", OR(B13="-", B13="", B13="#N/A")), "wait for return customer", IF(OR(B13="Local Scrap", B13="SBF to be notified", B13="VRAM is pending RTV", B13="BU未結案"), B13, IF(OR(B13="scrap結案", B13="良品結案", LEFT(B13,2)="sc", LEFT(B13,2)="良品"), "CND結案", IF(ISNUMBER(B13), YEAR(B13) & "Q" & INT((MONTH(B13)+2)/3), IF(ISERROR(DATEVALUE(TEXT(B13,"yyyy/mm/dd"))), IF(ISNA(B13), "#N/A", B13), YEAR(DATEVALUE(TEXT(B13,"yyyy/mm/dd"))) & "Q" & INT((MONTH(DATEVALUE(TEXT(B13,"yyyy/mm/dd")))+2)/3)))))))))) -> Standard Shipment | D13: =IF(C13="Local Scrap","Closed",IFERROR(IF(A13="kgb","Closed",IF(MID(C13,5,1)="Q","Closed",LOOKUP(TODAY()-W13, {0,31,91,181,366}, {"0-30天","31-90天","91-180天","181-365天","365天以上"}))), LOOKUP(TODAY()-Z13, {0,31,91,181,366}, {"0-30天","31-90天","91-180天","181-365天","365天以上"}))) -> Closed | E13: {=IF(A13<>"kbb", "", IF(IFERROR(VALUE(V13), 0)=MAX(INDEX(($A$2:$A$4929="kbb")*($L$2:$L$4929=L13)*IFERROR(VALUE($V$2:$V$4929), 0), 0)), "最新", "歷史重複"))} | F13: TO243000002 | G13: R | H13: PNY | I13: PNY_Asia | J13: 2024/03/05 16:35:59 | K13: 2024/03/04 11:16:54 | L13: HO23004593 | M13: 90CV07U100A0 | N13: RTX4060TI/PG190SKU361/GB/PNY | P13: HO23004593 | Q13: CLOSED | R13: 李景福 | S13: 2024/03/08 10:44:06 | T13: 2024/04/02 10:52:09 | U13: 2024/04/02 12:27:02 | V13: 2024/04/02 12:27:02 | Z13: 2024/03/08 10:25:31 | AA13: KEYIN | AB13: KEYIN | AC13: R10 | AD13: RTX4060TI | AE13: 2024/04/02 12:22:23 | AF13: 001 | AG13: 612776 | AH13: 1 | AI13: 1
A14: =IF(L14="","",IF(COUNTIF(Wip!K:K,L14)=0,IF(W14="","KGB","KBB"),IF(AND(_xlfn.IFNA(VLOOKUP(L14,Wip!K:M,3,0),"")="Y",Q14="MTCAPPLYCONF"),"On Hold",IF(W14="","KGB","KBB")))) -> KGB | B14: =IF(A14="on hold", "on hold", IF(A14="KGB", "Standard Shipment", IF(IFERROR(IFERROR(VLOOKUP(L14, List!D:J, 7, 0), VLOOKUP(L14&"", List!D:J, 7, 0)), 0)=0, IF(IFERROR(IFERROR(VLOOKUP(L14, 'CND List'!$A:$C, 3, 0), VLOOKUP(L14&"", 'CND List'!$A:$C, 3, 0)), 0)=0, IF(A14="KBB", "-", ""), IFERROR(VLOOKUP(L14, 'CND List'!$A:$C, 3, 0), VLOOKUP(L14&"", 'CND List'!$A:$C, 3, 0)) ), IFERROR(VLOOKUP(L14, List!D:J, 7, 0), VLOOKUP(L14&"", List!D:J, 7, 0)) ) ) ) -> Standard Shipment | C14: =IF(A14="on hold", "on hold", IF(B14="on hold", "wait for return customer", IF(B14="CND Sceond Pass", "Standard Shipment", IF(AND(A14="kgb", OR(B14="-", B14="", B14="#N/A")), "Standard Shipment", IF(AND(A14="kbb", OR(B14="-", B14="", B14="#N/A")), "wait for return customer", IF(OR(B14="Local Scrap", B14="SBF to be notified", B14="VRAM is pending RTV", B14="BU未結案"), B14, IF(OR(B14="scrap結案", B14="良品結案", LEFT(B14,2)="sc", LEFT(B14,2)="良品"), "CND結案", IF(ISNUMBER(B14), YEAR(B14) & "Q" & INT((MONTH(B14)+2)/3), IF(ISERROR(DATEVALUE(TEXT(B14,"yyyy/mm/dd"))), IF(ISNA(B14), "#N/A", B14), YEAR(DATEVALUE(TEXT(B14,"yyyy/mm/dd"))) & "Q" & INT((MONTH(DATEVALUE(TEXT(B14,"yyyy/mm/dd")))+2)/3)))))))))) -> Standard Shipment | D14: =IF(C14="Local Scrap","Closed",IFERROR(IF(A14="kgb","Closed",IF(MID(C14,5,1)="Q","Closed",LOOKUP(TODAY()-W14, {0,31,91,181,366}, {"0-30天","31-90天","91-180天","181-365天","365天以上"}))), LOOKUP(TODAY()-Z14, {0,31,91,181,366}, {"0-30天","31-90天","91-180天","181-365天","365天以上"}))) -> Closed | E14: {=IF(A14<>"kbb", "", IF(IFERROR(VALUE(V14), 0)=MAX(INDEX(($A$2:$A$4929="kbb")*($L$2:$L$4929=L14)*IFERROR(VALUE($V$2:$V$4929), 0), 0)), "最新", "歷史重複"))} | F14: TO243000002 | G14: R | H14: PNY | I14: PNY_Asia | J14: 2024/03/05 16:35:59 | K14: 2024/03/04 11:16:54 | L14: H823000537 | M14: 90CV07T10050 | N14: RTX4060/PG173-SKU371/GB/PNY | P14: H823000537 | Q14: CLOSED | R14: 李景福 | S14: 2024/03/08 10:44:06 | T14: 2024/04/25 12:34:28 | U14: 2024/04/30 16:55:58 | V14: 2024/04/30 16:55:58 | Z14: 2024/03/08 10:36:05 | AA14: KEYIN | AB14: KEYIN | AC14: R10 | AD14: RTX4060 | AE14: 2024/04/30 16:55:37 | AF14: 001 | AG14: 613632 | AH14: 1 | AI14: 1
A15: =IF(L15="","",IF(COUNTIF(Wip!K:K,L15)=0,IF(W15="","KGB","KBB"),IF(AND(_xlfn.IFNA(VLOOKUP(L15,Wip!K:M,3,0),"")="Y",Q15="MTCAPPLYCONF"),"On Hold",IF(W15="","KGB","KBB")))) -> KBB | B15: =IF(A15="on hold", "on hold", IF(A15="KGB", "Standard Shipment", IF(IFERROR(IFERROR(VLOOKUP(L15, List!D:J, 7, 0), VLOOKUP(L15&"", List!D:J, 7, 0)), 0)=0, IF(IFERROR(IFERROR(VLOOKUP(L15, 'CND List'!$A:$C, 3, 0), VLOOKUP(L15&"", 'CND List'!$A:$C, 3, 0)), 0)=0, IF(A15="KBB", "-", ""), IFERROR(VLOOKUP(L15, 'CND List'!$A:$C, 3, 0), VLOOKUP(L15&"", 'CND List'!$A:$C, 3, 0)) ), IFERROR(VLOOKUP(L15, List!D:J, 7, 0), VLOOKUP(L15&"", List!D:J, 7, 0)) ) ) ) -> 45384 | C15: =IF(A15="on hold", "on hold", IF(B15="on hold", "wait for return customer", IF(B15="CND Sceond Pass", "Standard Shipment", IF(AND(A15="kgb", OR(B15="-", B15="", B15="#N/A")), "Standard Shipment", IF(AND(A15="kbb", OR(B15="-", B15="", B15="#N/A")), "wait for return customer", IF(OR(B15="Local Scrap", B15="SBF to be notified", B15="VRAM is pending RTV", B15="BU未結案"), B15, IF(OR(B15="scrap結案", B15="良品結案", LEFT(B15,2)="sc", LEFT(B15,2)="良品"), "CND結案", IF(ISNUMBER(B15), YEAR(B15) & "Q" & INT((MONTH(B15)+2)/3), IF(ISERROR(DATEVALUE(TEXT(B15,"yyyy/mm/dd"))), IF(ISNA(B15), "#N/A", B15), YEAR(DATEVALUE(TEXT(B15,"yyyy/mm/dd"))) & "Q" & INT((MONTH(DATEVALUE(TEXT(B15,"yyyy/mm/dd")))+2)/3)))))))))) -> 2024Q2 | D15: =IF(C15="Local Scrap","Closed",IFERROR(IF(A15="kgb","Closed",IF(MID(C15,5,1)="Q","Closed",LOOKUP(TODAY()-W15, {0,31,91,181,366}, {"0-30天","31-90天","91-180天","181-365天","365天以上"}))), LOOKUP(TODAY()-Z15, {0,31,91,181,366}, {"0-30天","31-90天","91-180天","181-365天","365天以上"}))) -> Closed | E15: {=IF(A15<>"kbb", "", IF(IFERROR(VALUE(V15), 0)=MAX(INDEX(($A$2:$A$4929="kbb")*($L$2:$L$4929=L15)*IFERROR(VALUE($V$2:$V$4929), 0), 0)), "最新", "歷史重複"))} -> 最新 | F15: TO243000011 | G15: R | H15: PNY | I15: PNY_Asia | J15: 2024/03/25 13:07:38 | K15: 2024/03/21 16:49:30 | L15: H723004429 | M15: 69CV07T10A11 | N15: RTX4060/PG173-SKU371/STD/PNY | P15: H723004429 | Q15: CLOSED | R15: 李景福 | S15: 2024/04/02 11:14:42 | V15: 2024/04/02 11:22:18 | W15: [A3SC0030]Burnt Component | X15: Customer | Y15: PCB Burned/Q28 | Z15: 2024/04/02 11:04:52 | AA15: KEYIN | AB15: KEYIN | AC15: C01 | AD15: RTX4060
A16: =IF(L16="","",IF(COUNTIF(Wip!K:K,L16)=0,IF(W16="","KGB","KBB"),IF(AND(_xlfn.IFNA(VLOOKUP(L16,Wip!K:M,3,0),"")="Y",Q16="MTCAPPLYCONF"),"On Hold",IF(W16="","KGB","KBB")))) -> KGB | B16: =IF(A16="on hold", "on hold", IF(A16="KGB", "Standard Shipment", IF(IFERROR(IFERROR(VLOOKUP(L16, List!D:J, 7, 0), VLOOKUP(L16&"", List!D:J, 7, 0)), 0)=0, IF(IFERROR(IFERROR(VLOOKUP(L16, 'CND List'!$A:$C, 3, 0), VLOOKUP(L16&"", 'CND List'!$A:$C, 3, 0)), 0)=0, IF(A16="KBB", "-", ""), IFERROR(VLOOKUP(L16, 'CND List'!$A:$C, 3, 0), VLOOKUP(L16&"", 'CND List'!$A:$C, 3, 0)) ), IFERROR(VLOOKUP(L16, List!D:J, 7, 0), VLOOKUP(L16&"", List!D:J, 7, 0)) ) ) ) -> Standard Shipment | C16: =IF(A16="on hold", "on hold", IF(B16="on hold", "wait for return customer", IF(B16="CND Sceond Pass", "Standard Shipment", IF(AND(A16="kgb", OR(B16="-", B16="", B16="#N/A")), "Standard Shipment", IF(AND(A16="kbb", OR(B16="-", B16="", B16="#N/A")), "wait for return customer", IF(OR(B16="Local Scrap", B16="SBF to be notified", B16="VRAM is pending RTV", B16="BU未結案"), B16, IF(OR(B16="scrap結案", B16="良品結案", LEFT(B16,2)="sc", LEFT(B16,2)="良品"), "CND結案", IF(ISNUMBER(B16), YEAR(B16) & "Q" & INT((MONTH(B16)+2)/3), IF(ISERROR(DATEVALUE(TEXT(B16,"yyyy/mm/dd"))), IF(ISNA(B16), "#N/A", B16), YEAR(DATEVALUE(TEXT(B16,"yyyy/mm/dd"))) & "Q" & INT((MONTH(DATEVALUE(TEXT(B16,"yyyy/mm/dd")))+2)/3)))))))))) -> Standard Shipment | D16: =IF(C16="Local Scrap","Closed",IFERROR(IF(A16="kgb","Closed",IF(MID(C16,5,1)="Q","Closed",LOOKUP(TODAY()-W16, {0,31,91,181,366}, {"0-30天","31-90天","91-180天","181-365天","365天以上"}))), LOOKUP(TODAY()-Z16, {0,31,91,181,366}, {"0-30天","31-90天","91-180天","181-365天","365天以上"}))) -> Closed | E16: {=IF(A16<>"kbb", "", IF(IFERROR(VALUE(V16), 0)=MAX(INDEX(($A$2:$A$4929="kbb")*($L$2:$L$4929=L16)*IFERROR(VALUE($V$2:$V$4929), 0), 0)), "最新", "歷史重複"))} | F16: TO243000011 | G16: R | H16: PNY | I16: PNY_Asia | J16: 2024/03/25 13:07:38 | K16: 2024/03/21 16:49:30 | L16: HO23004530 | M16: 69CV07U10A11 | N16: RTX4060TI/PG190SKU361/STD/PNY | P16: HO23004530 | Q16: CLOSED | R16: 李景福 | S16: 2024/04/01 16:01:33 | T16: 2024/05/02 12:15:22 | U16: 2024/05/09 08:18:09 | V16: 2024/05/09 08:18:09 | Z16: 2024/04/01 15:49:32 | AA16: KEYIN | AB16: KEYIN | AC16: R10 | AD16: RTX4060TI | AE16: 2024/05/09 08:17:50 | AF16: 001 | AG16: 613861 | AH16: 1 | AI16: 1
A17: =IF(L17="","",IF(COUNTIF(Wip!K:K,L17)=0,IF(W17="","KGB","KBB"),IF(AND(_xlfn.IFNA(VLOOKUP(L17,Wip!K:M,3,0),"")="Y",Q17="MTCAPPLYCONF"),"On Hold",IF(W17="","KGB","KBB")))) -> KGB | B17: =IF(A17="on hold", "on hold", IF(A17="KGB", "Standard Shipment", IF(IFERROR(IFERROR(VLOOKUP(L17, List!D:J, 7, 0), VLOOKUP(L17&"", List!D:J, 7, 0)), 0)=0, IF(IFERROR(IFERROR(VLOOKUP(L17, 'CND List'!$A:$C, 3, 0), VLOOKUP(L17&"", 'CND List'!$A:$C, 3, 0)), 0)=0, IF(A17="KBB", "-", ""), IFERROR(VLOOKUP(L17, 'CND List'!$A:$C, 3, 0), VLOOKUP(L17&"", 'CND List'!$A:$C, 3, 0)) ), IFERROR(VLOOKUP(L17, List!D:J, 7, 0), VLOOKUP(L17&"", List!D:J, 7, 0)) ) ) ) -> Standard Shipment | C17: =IF(A17="on hold", "on hold", IF(B17="on hold", "wait for return customer", IF(B17="CND Sceond Pass", "Standard Shipment", IF(AND(A17="kgb", OR(B17="-", B17="", B17="#N/A")), "Standard Shipment", IF(AND(A17="kbb", OR(B17="-", B17="", B17="#N/A")), "wait for return customer", IF(OR(B17="Local Scrap", B17="SBF to be notified", B17="VRAM is pending RTV", B17="BU未結案"), B17, IF(OR(B17="scrap結案", B17="良品結案", LEFT(B17,2)="sc", LEFT(B17,2)="良品"), "CND結案", IF(ISNUMBER(B17), YEAR(B17) & "Q" & INT((MONTH(B17)+2)/3), IF(ISERROR(DATEVALUE(TEXT(B17,"yyyy/mm/dd"))), IF(ISNA(B17), "#N/A", B17), YEAR(DATEVALUE(TEXT(B17,"yyyy/mm/dd"))) & "Q" & INT((MONTH(DATEVALUE(TEXT(B17,"yyyy/mm/dd")))+2)/3)))))))))) -> Standard Shipment | D17: =IF(C17="Local Scrap","Closed",IFERROR(IF(A17="kgb","Closed",IF(MID(C17,5,1)="Q","Closed",LOOKUP(TODAY()-W17, {0,31,91,181,366}, {"0-30天","31-90天","91-180天","181-365天","365天以上"}))), LOOKUP(TODAY()-Z17, {0,31,91,181,366}, {"0-30天","31-90天","91-180天","181-365天","365天以上"}))) -> Closed | E17: {=IF(A17<>"kbb", "", IF(IFERROR(VALUE(V17), 0)=MAX(INDEX(($A$2:$A$4929="kbb")*($L$2:$L$4929=L17)*IFERROR(VALUE($V$2:$V$4929), 0), 0)), "最新", "歷史重複"))} | F17: TO243000011 | G17: R | H17: PNY | I17: PNY_Asia | J17: 2024/03/25 13:07:38 | K17: 2024/03/21 16:49:30 | L17: HO23004468 | M17: 69CV07U10A11 | N17: RTX4060TI/PG190SKU361/STD/PNY | P17: HO23004468 | Q17: CLOSED | R17: 李景福 | S17: 2024/04/01 16:01:33 | T17: 2024/05/02 12:15:07 | U17: 2024/05/09 08:18:09 | V17: 2024/05/09 08:18:09 | Z17: 2024/04/01 15:47:22 | AA17: KEYIN | AB17: KEYIN | AC17: R10 | AD17: RTX4060TI | AE17: 2024/05/09 08:17:50 | AF17: 001 | AG17: 613861 | AH17: 1 | AI17: 1
A18: =IF(L18="","",IF(COUNTIF(Wip!K:K,L18)=0,IF(W18="","KGB","KBB"),IF(AND(_xlfn.IFNA(VLOOKUP(L18,Wip!K:M,3,0),"")="Y",Q18="MTCAPPLYCONF"),"On Hold",IF(W18="","KGB","KBB")))) -> KGB | B18: =IF(A18="on hold", "on hold", IF(A18="KGB", "Standard Shipment", IF(IFERROR(IFERROR(VLOOKUP(L18, List!D:J, 7, 0), VLOOKUP(L18&"", List!D:J, 7, 0)), 0)=0, IF(IFERROR(IFERROR(VLOOKUP(L18, 'CND List'!$A:$C, 3, 0), VLOOKUP(L18&"", 'CND List'!$A:$C, 3, 0)), 0)=0, IF(A18="KBB", "-", ""), IFERROR(VLOOKUP(L18, 'CND List'!$A:$C, 3, 0), VLOOKUP(L18&"", 'CND List'!$A:$C, 3, 0)) ), IFERROR(VLOOKUP(L18, List!D:J, 7, 0), VLOOKUP(L18&"", List!D:J, 7, 0)) ) ) ) -> Standard Shipment | C18: =IF(A18="on hold", "on hold", IF(B18="on hold", "wait for return customer", IF(B18="CND Sceond Pass", "Standard Shipment", IF(AND(A18="kgb", OR(B18="-", B18="", B18="#N/A")), "Standard Shipment", IF(AND(A18="kbb", OR(B18="-", B18="", B18="#N/A")), "wait for return customer", IF(OR(B18="Local Scrap", B18="SBF to be notified", B18="VRAM is pending RTV", B18="BU未結案"), B18, IF(OR(B18="scrap結案", B18="良品結案", LEFT(B18,2)="sc", LEFT(B18,2)="良品"), "CND結案", IF(ISNUMBER(B18), YEAR(B18) & "Q" & INT((MONTH(B18)+2)/3), IF(ISERROR(DATEVALUE(TEXT(B18,"yyyy/mm/dd"))), IF(ISNA(B18), "#N/A", B18), YEAR(DATEVALUE(TEXT(B18,"yyyy/mm/dd"))) & "Q" & INT((MONTH(DATEVALUE(TEXT(B18,"yyyy/mm/dd")))+2)/3)))))))))) -> Standard Shipment | D18: =IF(C18="Local Scrap","Closed",IFERROR(IF(A18="kgb","Closed",IF(MID(C18,5,1)="Q","Closed",LOOKUP(TODAY()-W18, {0,31,91,181,366}, {"0-30天","31-90天","91-180天","181-365天","365天以上"}))), LOOKUP(TODAY()-Z18, {0,31,91,181,366}, {"0-30天","31-90天","91-180天","181-365天","365天以上"}))) -> Closed | E18: {=IF(A18<>"kbb", "", IF(IFERROR(VALUE(V18), 0)=MAX(INDEX(($A$2:$A$4929="kbb")*($L$2:$L$4929=L18)*IFERROR(VALUE($V$2:$V$4929), 0), 0)), "最新", "歷史重複"))} | F18: TO243000011 | G18: R | H18: PNY | I18: PNY_Asia | J18: 2024/03/25 13:07:38 | K18: 2024/03/21 16:49:30 | L18: H723001173 | M18: 69CV07T10A01 | N18: RTX4060/PG173-SKU371/STD/PNY | P18: H723001173 | Q18: CLOSED | R18: 李景福 | S18: 2024/04/01 16:01:33 | T18: 2024/04/25 12:33:54 | U18: 2024/04/30 16:55:58 | V18: 2024/04/30 16:55:58 | Z18: 2024/04/01 15:50:14 | AA18: KEYIN | AB18: KEYIN | AC18: R10 | AD18: RTX4060 | AE18: 2024/04/30 16:55:36 | AF18: 001 | AG18: 613632 | AH18: 1 | AI18: 1
A19: =IF(L19="","",IF(COUNTIF(Wip!K:K,L19)=0,IF(W19="","KGB","KBB"),IF(AND(_xlfn.IFNA(VLOOKUP(L19,Wip!K:M,3,0),"")="Y",Q19="MTCAPPLYCONF"),"On Hold",IF(W19="","KGB","KBB")))) -> KGB | B19: =IF(A19="on hold", "on hold", IF(A19="KGB", "Standard Shipment", IF(IFERROR(IFERROR(VLOOKUP(L19, List!D:J, 7, 0), VLOOKUP(L19&"", List!D:J, 7, 0)), 0)=0, IF(IFERROR(IFERROR(VLOOKUP(L19, 'CND List'!$A:$C, 3, 0), VLOOKUP(L19&"", 'CND List'!$A:$C, 3, 0)), 0)=0, IF(A19="KBB", "-", ""), IFERROR(VLOOKUP(L19, 'CND List'!$A:$C, 3, 0), VLOOKUP(L19&"", 'CND List'!$A:$C, 3, 0)) ), IFERROR(VLOOKUP(L19, List!D:J, 7, 0), VLOOKUP(L19&"", List!D:J, 7, 0)) ) ) ) -> Standard Shipment | C19: =IF(A19="on hold", "on hold", IF(B19="on hold", "wait for return customer", IF(B19="CND Sceond Pass", "Standard Shipment", IF(AND(A19="kgb", OR(B19="-", B19="", B19="#N/A")), "Standard Shipment", IF(AND(A19="kbb", OR(B19="-", B19="", B19="#N/A")), "wait for return customer", IF(OR(B19="Local Scrap", B19="SBF to be notified", B19="VRAM is pending RTV", B19="BU未結案"), B19, IF(OR(B19="scrap結案", B19="良品結案", LEFT(B19,2)="sc", LEFT(B19,2)="良品"), "CND結案", IF(ISNUMBER(B19), YEAR(B19) & "Q" & INT((MONTH(B19)+2)/3), IF(ISERROR(DATEVALUE(TEXT(B19,"yyyy/mm/dd"))), IF(ISNA(B19), "#N/A", B19), YEAR(DATEVALUE(TEXT(B19,"yyyy/mm/dd"))) & "Q" & INT((MONTH(DATEVALUE(TEXT(B19,"yyyy/mm/dd")))+2)/3)))))))))) -> Standard Shipment | D19: =IF(C19="Local Scrap","Closed",IFERROR(IF(A19="kgb","Closed",IF(MID(C19,5,1)="Q","Closed",LOOKUP(TODAY()-W19, {0,31,91,181,366}, {"0-30天","31-90天","91-180天","181-365天","365天以上"}))), LOOKUP(TODAY()-Z19, {0,31,91,181,366}, {"0-30天","31-90天","91-180天","181-365天","365天以上"}))) -> Closed | E19: {=IF(A19<>"kbb", "", IF(IFERROR(VALUE(V19), 0)=MAX(INDEX(($A$2:$A$4929="kbb")*($L$2:$L$4929=L19)*IFERROR(VALUE($V$2:$V$4929), 0), 0)), "最新", "歷史重複"))} | F19: TO244000002 | G19: R | H19: PNY | I19: PNY_Asia | J19: 2024/04/15 15:54:05 | K19: 2024/04/10 15:24:59 | L19: 242049769000676 | M19: 90CV07T10090 | N19: RTX4060/PG173-SKU371/GB/PNY | P19: 242049769000676 | Q19: CLOSED | R19: 李景福 | S19: 2024/04/18 14:00:22 | T19: 2024/04/25 12:36:16 | U19: 2024/04/30 16:55:58 | V19: 2024/04/30 16:55:58 | Z19: 2024/04/18 13:54:24 | AA19: KEYIN | AB19: KEYIN | AC19: R10 | AD19: RTX4060 | AE19: 2024/04/30 16:55:37 | AF19: 001 | AG19: 613632 | AH19: 1 | AI19: 1
A20: =IF(L20="","",IF(COUNTIF(Wip!K:K,L20)=0,IF(W20="","KGB","KBB"),IF(AND(_xlfn.IFNA(VLOOKUP(L20,Wip!K:M,3,0),"")="Y",Q20="MTCAPPLYCONF"),"On Hold",IF(W20="","KGB","KBB")))) -> KGB | B20: =IF(A20="on hold", "on hold", IF(A20="KGB", "Standard Shipment", IF(IFERROR(IFERROR(VLOOKUP(L20, List!D:J, 7, 0), VLOOKUP(L20&"", List!D:J, 7, 0)), 0)=0, IF(IFERROR(IFERROR(VLOOKUP(L20, 'CND List'!$A:$C, 3, 0), VLOOKUP(L20&"", 'CND List'!$A:$C, 3, 0)), 0)=0, IF(A20="KBB", "-", ""), IFERROR(VLOOKUP(L20, 'CND List'!$A:$C, 3, 0), VLOOKUP(L20&"", 'CND List'!$A:$C, 3, 0)) ), IFERROR(VLOOKUP(L20, List!D:J, 7, 0), VLOOKUP(L20&"", List!D:J, 7, 0)) ) ) ) -> Standard Shipment | C20: =IF(A20="on hold", "on hold", IF(B20="on hold", "wait for return customer", IF(B20="CND Sceond Pass", "Standard Shipment", IF(AND(A20="kgb", OR(B20="-", B20="", B20="#N/A")), "Standard Shipment", IF(AND(A20="kbb", OR(B20="-", B20="", B20="#N/A")), "wait for return customer", IF(OR(B20="Local Scrap", B20="SBF to be notified", B20="VRAM is pending RTV", B20="BU未結案"), B20, IF(OR(B20="scrap結案", B20="良品結案", LEFT(B20,2)="sc", LEFT(B20,2)="良品"), "CND結案", IF(ISNUMBER(B20), YEAR(B20) & "Q" & INT((MONTH(B20)+2)/3), IF(ISERROR(DATEVALUE(TEXT(B20,"yyyy/mm/dd"))), IF(ISNA(B20), "#N/A", B20), YEAR(DATEVALUE(TEXT(B20,"yyyy/mm/dd"))) & "Q" & INT((MONTH(DATEVALUE(TEXT(B20,"yyyy/mm/dd")))+2)/3)))))))))) -> Standard Shipment | D20: =IF(C20="Local Scrap","Closed",IFERROR(IF(A20="kgb","Closed",IF(MID(C20,5,1)="Q","Closed",LOOKUP(TODAY()-W20, {0,31,91,181,366}, {"0-30天","31-90天","91-180天","181-365天","365天以上"}))), LOOKUP(TODAY()-Z20, {0,31,91,181,366}, {"0-30天","31-90天","91-180天","181-365天","365天以上"}))) -> Closed | E20: {=IF(A20<>"kbb", "", IF(IFERROR(VALUE(V20), 0)=MAX(INDEX(($A$2:$A$4929="kbb")*($L$2:$L$4929=L20)*IFERROR(VALUE($V$2:$V$4929), 0), 0)), "最新", "歷史重複"))} | F20: TO244000002 | G20: R | H20: PNY | I20: PNY_Asia | J20: 2024/04/15 15:54:05 | K20: 2024/04/10 15:24:59 | L20: 242125079000196 | M20: 90CV07U10010 | N20: RTX4060TI/PG190SKU361/GB/PNY | P20: 242125079000196 | Q20: CLOSED | R20: 吳崇源 | S20: 2024/04/18 14:00:22 | T20: 2024/05/02 11:07:52 | U20: 2024/06/05 17:02:43 | V20: 2024/06/05 17:02:43 | Z20: 2024/04/18 13:56:13 | AA20: KEYIN | AB20: KEYIN | AC20: R10 | AD20: RTX4060TI | AE20: 2024/06/05 17:02:31 | AF20: 001 | AG20: 614670 | AH20: 1 | AI20: 1
A21: =IF(L21="","",IF(COUNTIF(Wip!K:K,L21)=0,IF(W21="","KGB","KBB"),IF(AND(_xlfn.IFNA(VLOOKUP(L21,Wip!K:M,3,0),"")="Y",Q21="MTCAPPLYCONF"),"On Hold",IF(W21="","KGB","KBB")))) -> KGB | B21: =IF(A21="on hold", "on hold", IF(A21="KGB", "Standard Shipment", IF(IFERROR(IFERROR(VLOOKUP(L21, List!D:J, 7, 0), VLOOKUP(L21&"", List!D:J, 7, 0)), 0)=0, IF(IFERROR(IFERROR(VLOOKUP(L21, 'CND List'!$A:$C, 3, 0), VLOOKUP(L21&"", 'CND List'!$A:$C, 3, 0)), 0)=0, IF(A21="KBB", "-", ""), IFERROR(VLOOKUP(L21, 'CND List'!$A:$C, 3, 0), VLOOKUP(L21&"", 'CND List'!$A:$C, 3, 0)) ), IFERROR(VLOOKUP(L21, List!D:J, 7, 0), VLOOKUP(L21&"", List!D:J, 7, 0)) ) ) ) -> Standard Shipment | C21: =IF(A21="on hold", "on hold", IF(B21="on hold", "wait for return customer", IF(B21="CND Sceond Pass", "Standard Shipment", IF(AND(A21="kgb", OR(B21="-", B21="", B21="#N/A")), "Standard Shipment", IF(AND(A21="kbb", OR(B21="-", B21="", B21="#N/A")), "wait for return customer", IF(OR(B21="Local Scrap", B21="SBF to be notified", B21="VRAM is pending RTV", B21="BU未結案"), B21, IF(OR(B21="scrap結案", B21="良品結案", LEFT(B21,2)="sc", LEFT(B21,2)="良品"), "CND結案", IF(ISNUMBER(B21), YEAR(B21) & "Q" & INT((MONTH(B21)+2)/3), IF(ISERROR(DATEVALUE(TEXT(B21,"yyyy/mm/dd"))), IF(ISNA(B21), "#N/A", B21), YEAR(DATEVALUE(TEXT(B21,"yyyy/mm/dd"))) & "Q" & INT((MONTH(DATEVALUE(TEXT(B21,"yyyy/mm/dd")))+2)/3)))))))))) -> Standard Shipment | D21: =IF(C21="Local Scrap","Closed",IFERROR(IF(A21="kgb","Closed",IF(MID(C21,5,1)="Q","Closed",LOOKUP(TODAY()-W21, {0,31,91,181,366}, {"0-30天","31-90天","91-180天","181-365天","365天以上"}))), LOOKUP(TODAY()-Z21, {0,31,91,181,366}, {"0-30天","31-90天","91-180天","181-365天","365天以上"}))) -> Closed | E21: {=IF(A21<>"kbb", "", IF(IFERROR(VALUE(V21), 0)=MAX(INDEX(($A$2:$A$4929="kbb")*($L$2:$L$4929=L21)*IFERROR(VALUE($V$2:$V$4929), 0), 0)), "最新", "歷史重複"))} | F21: TO244000002 | G21: R | H21: PNY | I21: PNY_Asia | J21: 2024/04/15 15:54:05 | K21: 2024/04/10 15:24:59 | L21: 242125079000973 | M21: 90CV07U10010 | N21: RTX4060TI/PG190SKU361/GB/PNY | P21: 242125079000973 | Q21: CLOSED | R21: 李景福 | S21: 2024/04/18 14:00:22 | T21: 2024/05/02 12:15:43 | U21: 2024/05/09 08:18:09 | V21: 2024/05/09 08:18:09 | Z21: 2024/04/18 13:59:02 | AA21: KEYIN | AB21: KEYIN | AC21: R10 | AD21: RTX4060TI | AE21: 2024/05/09 08:17:50 | AF21: 001 | AG21: 613861 | AH21: 1 | AI21: 1
A22: =IF(L22="","",IF(COUNTIF(Wip!K:K,L22)=0,IF(W22="","KGB","KBB"),IF(AND(_xlfn.IFNA(VLOOKUP(L22,Wip!K:M,3,0),"")="Y",Q22="MTCAPPLYCONF"),"On Hold",IF(W22="","KGB","KBB")))) -> KGB | B22: =IF(A22="on hold", "on hold", IF(A22="KGB", "Standard Shipment", IF(IFERROR(IFERROR(VLOOKUP(L22, List!D:J, 7, 0), VLOOKUP(L22&"", List!D:J, 7, 0)), 0)=0, IF(IFERROR(IFERROR(VLOOKUP(L22, 'CND List'!$A:$C, 3, 0), VLOOKUP(L22&"", 'CND List'!$A:$C, 3, 0)), 0)=0, IF(A22="KBB", "-", ""), IFERROR(VLOOKUP(L22, 'CND List'!$A:$C, 3, 0), VLOOKUP(L22&"", 'CND List'!$A:$C, 3, 0)) ), IFERROR(VLOOKUP(L22, List!D:J, 7, 0), VLOOKUP(L22&"", List!D:J, 7, 0)) ) ) ) -> Standard Shipment | C22: =IF(A22="on hold", "on hold", IF(B22="on hold", "wait for return customer", IF(B22="CND Sceond Pass", "Standard Shipment", IF(AND(A22="kgb", OR(B22="-", B22="", B22="#N/A")), "Standard Shipment", IF(AND(A22="kbb", OR(B22="-", B22="", B22="#N/A")), "wait for return customer", IF(OR(B22="Local Scrap", B22="SBF to be notified", B22="VRAM is pending RTV", B22="BU未結案"), B22, IF(OR(B22="scrap結案", B22="良品結案", LEFT(B22,2)="sc", LEFT(B22,2)="良品"), "CND結案", IF(ISNUMBER(B22), YEAR(B22) & "Q" & INT((MONTH(B22)+2)/3), IF(ISERROR(DATEVALUE(TEXT(B22,"yyyy/mm/dd"))), IF(ISNA(B22), "#N/A", B22), YEAR(DATEVALUE(TEXT(B22,"yyyy/mm/dd"))) & "Q" & INT((MONTH(DATEVALUE(TEXT(B22,"yyyy/mm/dd")))+2)/3)))))))))) -> Standard Shipment | D22: =IF(C22="Local Scrap","Closed",IFERROR(IF(A22="kgb","Closed",IF(MID(C22,5,1)="Q","Closed",LOOKUP(TODAY()-W22, {0,31,91,181,366}, {"0-30天","31-90天","91-180天","181-365天","365天以上"}))), LOOKUP(TODAY()-Z22, {0,31,91,181,366}, {"0-30天","31-90天","91-180天","181-365天","365天以上"}))) -> Closed | E22: {=IF(A22<>"kbb", "", IF(IFERROR(VALUE(V22), 0)=MAX(INDEX(($A$2:$A$4929="kbb")*($L$2:$L$4929=L22)*IFERROR(VALUE($V$2:$V$4929), 0), 0)), "最新", "歷史重複"))} | F22: TO244000002 | G22: R | H22: PNY | I22: PNY_Asia | J22: 2024/04/15 15:54:05 | K22: 2024/04/10 15:24:59 | L22: 242049759001691 | M22: 90CV07T10090 | N22: RTX4060/PG173-SKU371/GB/PNY | P22: 242049759001691 | Q22: CLOSED | R22: 李景福 | S22: 2024/04/18 14:00:22 | T22: 2024/04/25 12:36:26 | U22: 2024/04/30 16:55:58 | V22: 2024/04/30 16:55:58 | Z22: 2024/04/18 13:55:29 | AA22: KEYIN | AB22: KEYIN | AC22: R10 | AD22: RTX4060 | AE22: 2024/04/30 16:55:37 | AF22: 001 | AG22: 613632 | AH22: 1 | AI22: 1
A23: =IF(L23="","",IF(COUNTIF(Wip!K:K,L23)=0,IF(W23="","KGB","KBB"),IF(AND(_xlfn.IFNA(VLOOKUP(L23,Wip!K:M,3,0),"")="Y",Q23="MTCAPPLYCONF"),"On Hold",IF(W23="","KGB","KBB")))) -> KGB | B23: =IF(A23="on hold", "on hold", IF(A23="KGB", "Standard Shipment", IF(IFERROR(IFERROR(VLOOKUP(L23, List!D:J, 7, 0), VLOOKUP(L23&"", List!D:J, 7, 0)), 0)=0, IF(IFERROR(IFERROR(VLOOKUP(L23, 'CND List'!$A:$C, 3, 0), VLOOKUP(L23&"", 'CND List'!$A:$C, 3, 0)), 0)=0, IF(A23="KBB", "-", ""), IFERROR(VLOOKUP(L23, 'CND List'!$A:$C, 3, 0), VLOOKUP(L23&"", 'CND List'!$A:$C, 3, 0)) ), IFERROR(VLOOKUP(L23, List!D:J, 7, 0), VLOOKUP(L23&"", List!D:J, 7, 0)) ) ) ) -> Standard Shipment | C23: =IF(A23="on hold", "on hold", IF(B23="on hold", "wait for return customer", IF(B23="CND Sceond Pass", "Standard Shipment", IF(AND(A23="kgb", OR(B23="-", B23="", B23="#N/A")), "Standard Shipment", IF(AND(A23="kbb", OR(B23="-", B23="", B23="#N/A")), "wait for return customer", IF(OR(B23="Local Scrap", B23="SBF to be notified", B23="VRAM is pending RTV", B23="BU未結案"), B23, IF(OR(B23="scrap結案", B23="良品結案", LEFT(B23,2)="sc", LEFT(B23,2)="良品"), "CND結案", IF(ISNUMBER(B23), YEAR(B23) & "Q" & INT((MONTH(B23)+2)/3), IF(ISERROR(DATEVALUE(TEXT(B23,"yyyy/mm/dd"))), IF(ISNA(B23), "#N/A", B23), YEAR(DATEVALUE(TEXT(B23,"yyyy/mm/dd"))) & "Q" & INT((MONTH(DATEVALUE(TEXT(B23,"yyyy/mm/dd")))+2)/3)))))))))) -> Standard Shipment | D23: =IF(C23="Local Scrap","Closed",IFERROR(IF(A23="kgb","Closed",IF(MID(C23,5,1)="Q","Closed",LOOKUP(TODAY()-W23, {0,31,91,181,366}, {"0-30天","31-90天","91-180天","181-365天","365天以上"}))), LOOKUP(TODAY()-Z23, {0,31,91,181,366}, {"0-30天","31-90天","91-180天","181-365天","365天以上"}))) -> Closed | E23: {=IF(A23<>"kbb", "", IF(IFERROR(VALUE(V23), 0)=MAX(INDEX(($A$2:$A$4929="kbb")*($L$2:$L$4929=L23)*IFERROR(VALUE($V$2:$V$4929), 0), 0)), "最新", "歷史重複"))} | F23: TO244000002 | G23: R | H23: PNY | I23: PNY_Asia | J23: 2024/04/15 15:54:05 | K23: 2024/04/10 15:24:59 | L23: 244113879001377 | M23: 90CV07T10010 | N23: RTX4060/PG173-SKU371/GB/PNY | P23: 244113879001377 | Q23: CLOSED | R23: 李景福 | S23: 2024/04/18 14:00:22 | T23: 2024/04/25 12:36:06 | U23: 2024/04/30 16:55:58 | V23: 2024/04/30 16:55:58 | Z23: 2024/04/18 13:59:59 | AA23: KEYIN | AB23: KEYIN | AC23: R10 | AD23: RTX4060 | AE23: 2024/04/30 16:55:37 | AF23: 001 | AG23: 613632 | AH23: 1 | AI23: 1
A24: =IF(L24="","",IF(COUNTIF(Wip!K:K,L24)=0,IF(W24="","KGB","KBB"),IF(AND(_xlfn.IFNA(VLOOKUP(L24,Wip!K:M,3,0),"")="Y",Q24="MTCAPPLYCONF"),"On Hold",IF(W24="","KGB","KBB")))) -> KGB | B24: =IF(A24="on hold", "on hold", IF(A24="KGB", "Standard Shipment", IF(IFERROR(IFERROR(VLOOKUP(L24, List!D:J, 7, 0), VLOOKUP(L24&"", List!D:J, 7, 0)), 0)=0, IF(IFERROR(IFERROR(VLOOKUP(L24, 'CND List'!$A:$C, 3, 0), VLOOKUP(L24&"", 'CND List'!$A:$C, 3, 0)), 0)=0, IF(A24="KBB", "-", ""), IFERROR(VLOOKUP(L24, 'CND List'!$A:$C, 3, 0), VLOOKUP(L24&"", 'CND List'!$A:$C, 3, 0)) ), IFERROR(VLOOKUP(L24, List!D:J, 7, 0), VLOOKUP(L24&"", List!D:J, 7, 0)) ) ) ) -> Standard Shipment | C24: =IF(A24="on hold", "on hold", IF(B24="on hold", "wait for return customer", IF(B24="CND Sceond Pass", "Standard Shipment", IF(AND(A24="kgb", OR(B24="-", B24="", B24="#N/A")), "Standard Shipment", IF(AND(A24="kbb", OR(B24="-", B24="", B24="#N/A")), "wait for return customer", IF(OR(B24="Local Scrap", B24="SBF to be notified", B24="VRAM is pending RTV", B24="BU未結案"), B24, IF(OR(B24="scrap結案", B24="良品結案", LEFT(B24,2)="sc", LEFT(B24,2)="良品"), "CND結案", IF(ISNUMBER(B24), YEAR(B24) & "Q" & INT((MONTH(B24)+2)/3), IF(ISERROR(DATEVALUE(TEXT(B24,"yyyy/mm/dd"))), IF(ISNA(B24), "#N/A", B24), YEAR(DATEVALUE(TEXT(B24,"yyyy/mm/dd"))) & "Q" & INT((MONTH(DATEVALUE(TEXT(B24,"yyyy/mm/dd")))+2)/3)))))))))) -> Standard Shipment | D24: =IF(C24="Local Scrap","Closed",IFERROR(IF(A24="kgb","Closed",IF(MID(C24,5,1)="Q","Closed",LOOKUP(TODAY()-W24, {0,31,91,181,366}, {"0-30天","31-90天","91-180天","181-365天","365天以上"}))), LOOKUP(TODAY()-Z24, {0,31,91,181,366}, {"0-30天","31-90天","91-180天","181-365天","365天以上"}))) -> Closed | E24: {=IF(A24<>"kbb", "", IF(IFERROR(VALUE(V24), 0)=MAX(INDEX(($A$2:$A$4929="kbb")*($L$2:$L$4929=L24)*IFERROR(VALUE($V$2:$V$4929), 0), 0)), "最新", "歷史重複"))} | F24: TO244000010 | G24: R | H24: PNY | I24: PNY_Asia | J24: 2024/05/06 14:51:25 | K24: 2024/04/30 12:44:09 | L24: 237968999000863 | M24: 69CV07T10A11 | N24: RTX4060/PG173-SKU371/STD/PNY | P24: 237968999000863 | Q24: CLOSED | R24: 吳崇源 | S24: 2024/05/07 16:16:18 | T24: 2024/05/08 17:48:50 | U24: 2024/05/21 08:25:08 | V24: 2024/05/21 08:25:08 | Z24: 2024/05/07 15:45:11 | AA24: KEYIN | AB24: KEYIN | AC24: R10 | AD24: RTX4060 | AE24: 2024/05/21 08:24:50 | AF24: 001 | AG24: 614205 | AH24: 1 | AI24: 1
A25: =IF(L25="","",IF(COUNTIF(Wip!K:K,L25)=0,IF(W25="","KGB","KBB"),IF(AND(_xlfn.IFNA(VLOOKUP(L25,Wip!K:M,3,0),"")="Y",Q25="MTCAPPLYCONF"),"On Hold",IF(W25="","KGB","KBB")))) -> KGB | B25: =IF(A25="on hold", "on hold", IF(A25="KGB", "Standard Shipment", IF(IFERROR(IFERROR(VLOOKUP(L25, List!D:J, 7, 0), VLOOKUP(L25&"", List!D:J, 7, 0)), 0)=0, IF(IFERROR(IFERROR(VLOOKUP(L25, 'CND List'!$A:$C, 3, 0), VLOOKUP(L25&"", 'CND List'!$A:$C, 3, 0)), 0)=0, IF(A25="KBB", "-", ""), IFERROR(VLOOKUP(L25, 'CND List'!$A:$C, 3, 0), VLOOKUP(L25&"", 'CND List'!$A:$C, 3, 0)) ), IFERROR(VLOOKUP(L25, List!D:J, 7, 0), VLOOKUP(L25&"", List!D:J, 7, 0)) ) ) ) -> Standard Shipment | C25: =IF(A25="on hold", "on hold", IF(B25="on hold", "wait for return customer", IF(B25="CND Sceond Pass", "Standard Shipment", IF(AND(A25="kgb", OR(B25="-", B25="", B25="#N/A")), "Standard Shipment", IF(AND(A25="kbb", OR(B25="-", B25="", B25="#N/A")), "wait for return customer", IF(OR(B25="Local Scrap", B25="SBF to be notified", B25="VRAM is pending RTV", B25="BU未結案"), B25, IF(OR(B25="scrap結案", B25="良品結案", LEFT(B25,2)="sc", LEFT(B25,2)="良品"), "CND結案", IF(ISNUMBER(B25), YEAR(B25) & "Q" & INT((MONTH(B25)+2)/3), IF(ISERROR(DATEVALUE(TEXT(B25,"yyyy/mm/dd"))), IF(ISNA(B25), "#N/A", B25), YEAR(DATEVALUE(TEXT(B25,"yyyy/mm/dd"))) & "Q" & INT((MONTH(DATEVALUE(TEXT(B25,"yyyy/mm/dd")))+2)/3)))))))))) -> Standard Shipment | D25: =IF(C25="Local Scrap","Closed",IFERROR(IF(A25="kgb","Closed",IF(MID(C25,5,1)="Q","Closed",LOOKUP(TODAY()-W25, {0,31,91,181,366}, {"0-30天","31-90天","91-180天","181-365天","365天以上"}))), LOOKUP(TODAY()-Z25, {0,31,91,181,366}, {"0-30天","31-90天","91-180天","181-365天","365天以上"}))) -> Closed | E25: {=IF(A25<>"kbb", "", IF(IFERROR(VALUE(V25), 0)=MAX(INDEX(($A$2:$A$4929="kbb")*($L$2:$L$4929=L25)*IFERROR(VALUE($V$2:$V$4929), 0), 0)), "最新", "歷史重複"))} | F25: TO244000010 | G25: R | H25: PNY | I25: PNY_Asia | J25: 2024/05/06 14:51:25 | K25: 2024/04/30 12:44:09 | L25: 245434689001791 | M25: 69CV07T10A12 | N25: RTX4060/PG173-SKU371/STD/PNY | P25: 245434689001791 | Q25: CLOSED | R25: 吳崇源 | S25: 2024/05/07 16:16:18 | T25: 2024/05/08 17:28:38 | U25: 2024/05/21 08:25:08 | V25: 2024/05/21 08:25:08 | Z25: 2024/05/07 16:11:51 | AA25: KEYIN | AB25: KEYIN | AC25: R10 | AD25: RTX4060 | AE25: 2024/05/21 08:24:50 | AF25: 001 | AG25: 614205 | AH25: 1 | AI25: 1
